Workbook

Sheet Accueil

Sheet 1-Demandes SAV
B3: 46254
B4: 46253
B5: 46248 | L5: 46252
B6: 46248 | L6: 46252
B7: 46246
B8: 46246
B9: 46246
B10: 46227
B11: 46211
B12: 46210
B13: 46174
B14: 46174
B15: 46174
B16: 46150
B17: 46028
B18: 46028
... B23: 46028
B24: 46023 | P24: 46087
P27: 46087
P28: 46087
P30: 46197

Sheet 2-Ma tournée
H5: =IFERROR(IF(INDEX('1-Demandes SAV'!$L$2:$L$601,MATCH(1,'1-Demandes SAV'!$AB$2:$AB$601,0))="","",INDEX('1-Demandes SAV'!$L$2:$L$601,MATCH(1,'1-Demandes SAV'!$AB$2:$AB$601,0))),"") -> 46252
H6: =IFERROR(IF(INDEX('1-Demandes SAV'!$L$2:$L$601,MATCH(2,'1-Demandes SAV'!$AB$2:$AB$601,0))="","",INDEX('1-Demandes SAV'!$L$2:$L$601,MATCH(2,'1-Demandes SAV'!$AB$2:$AB$601,0))),"") -> 46252

Sheet 3-Parc machines
R2: =IF($A2="","",IFERROR(_xlfn.MAXIFS('6-Historique'!$D$2:$D$1997,'6-Historique'!$B$2:$B$1997,$A2),"")) -> 46007
R3: =IF($A3="","",IFERROR(_xlfn.MAXIFS('6-Historique'!$D$2:$D$1997,'6-Historique'!$B$2:$B$1997,$A3),"")) -> 45359
R4: =IF($A4="","",IFERROR(_xlfn.MAXIFS('6-Historique'!$D$2:$D$1997,'6-Historique'!$B$2:$B$1997,$A4),"")) -> 0
R5: =IF($A5="","",IFERROR(_xlfn.MAXIFS('6-Historique'!$D$2:$D$1997,'6-Historique'!$B$2:$B$1997,$A5),"")) -> 0
R6: =IF($A6="","",IFERROR(_xlfn.MAXIFS('6-Historique'!$D$2:$D$1997,'6-Historique'!$B$2:$B$1997,$A6),"")) -> 43724 | T6: =IF($A6="","",IFERROR(INDEX('4-VGP'!$A$2:$A$334,MATCH($A6,'4-VGP'!$N$2:$N$334,0)),"")) -> 45748 | W6: =IF($T6="","",EDATE($T6,'8-Param'!$Q$2)) -> 46113
R7: =IF($A7="","",IFERROR(_xlfn.MAXIFS('6-Historique'!$D$2:$D$1997,'6-Historique'!$B$2:$B$1997,$A7),"")) -> 45989
R8: =IF($A8="","",IFERROR(_xlfn.MAXIFS('6-Historique'!$D$2:$D$1997,'6-Historique'!$B$2:$B$1997,$A8),"")) -> 0 | T8: =IF($A8="","",IFERROR(INDEX('4-VGP'!$A$2:$A$334,MATCH($A8,'4-VGP'!$N$2:$N$334,0)),"")) -> 45748 | W8: =IF($T8="","",EDATE($T8,'8-Param'!$Q$2)) -> 46113
R9: =IF($A9="","",IFERROR(_xlfn.MAXIFS('6-Historique'!$D$2:$D$1997,'6-Historique'!$B$2:$B$1997,$A9),"")) -> 45989
R10: =IF($A10="","",IFERROR(_xlfn.MAXIFS('6-Historique'!$D$2:$D$1997,'6-Historique'!$B$2:$B$1997,$A10),"")) -> 45846
R11: =IF($A11="","",IFERROR(_xlfn.MAXIFS('6-Historique'!$D$2:$D$1997,'6-Historique'!$B$2:$B$1997,$A11),"")) -> 45758
R12: =IF($A12="","",IFERROR(_xlfn.MAXIFS('6-Historique'!$D$2:$D$1997,'6-Historique'!$B$2:$B$1997,$A12),"")) -> 45688
R13: =IF($A13="","",IFERROR(_xlfn.MAXIFS('6-Historique'!$D$2:$D$1997,'6-Historique'!$B$2:$B$1997,$A13),"")) -> 0
R14: =IF($A14="","",IFERROR(_xlfn.MAXIFS('6-Historique'!$D$2:$D$1997,'6-Historique'!$B$2:$B$1997,$A14),"")) -> 46230 | T14: =IF($A14="","",IFERROR(INDEX('4-VGP'!$A$2:$A$334,MATCH($A14,'4-VGP'!$N$2:$N$334,0)),"")) -> 46097 | W14: =IF($T14="","",EDATE($T14,'8-Param'!$Q$2)) -> 46462
R15: =IF($A15="","",IFERROR(_xlfn.MAXIFS('6-Historique'!$D$2:$D$1997,'6-Historique'!$B$2:$B$1997,$A15),"")) -> 0
R16: =IF($A16="","",IFERROR(_xlfn.MAXIFS('6-Historique'!$D$2:$D$1997,'6-Historique'!$B$2:$B$1997,$A16),"")) -> 46092
R17: =IF($A17="","",IFERROR(_xlfn.MAXIFS('6-Historique'!$D$2:$D$1997,'6-Historique'!$B$2:$B$1997,$A17),"")) -> 0 | T17: =IF($A17="","",IFERROR(INDEX('4-VGP'!$A$2:$A$334,MATCH($A17,'4-VGP'!$N$2:$N$334,0)),"")) -> 45729 | W17: =IF($T17="","",EDATE($T17,'8-Param'!$Q$2)) -> 46094
R18: =IF($A18="","",IFERROR(_xlfn.MAXIFS('6-Historique'!$D$2:$D$1997,'6-Historique'!$B$2:$B$1997,$A18),"")) -> 0 | T18: =IF($A18="","",IFERROR(INDEX('4-VGP'!$A$2:$A$334,MATCH($A18,'4-VGP'!$N$2:$N$334,0)),"")) -> 45729 | W18: =IF($T18="","",EDATE($T18,'8-Param'!$Q$2)) -> 46094
R19: =IF($A19="","",IFERROR(_xlfn.MAXIFS('6-Historique'!$D$2:$D$1997,'6-Historique'!$B$2:$B$1997,$A19),"")) -> 0 | T19: =IF($A19="","",IFERROR(INDEX('4-VGP'!$A$2:$A$334,MATCH($A19,'4-VGP'!$N$2:$N$334,0)),"")) -> 45729 | W19: =IF($T19="","",EDATE($T19,'8-Param'!$Q$2)) -> 46094
R20: =IF($A20="","",IFERROR(_xlfn.MAXIFS('6-Historique'!$D$2:$D$1997,'6-Historique'!$B$2:$B$1997,$A20),"")) -> 0
R21: =IF($A21="","",IFERROR(_xlfn.MAXIFS('6-Historique'!$D$2:$D$1997,'6-Historique'!$B$2:$B$1997,$A21),"")) -> 0
R22: =IF($A22="","",IFERROR(_xlfn.MAXIFS('6-Historique'!$D$2:$D$1997,'6-Historique'!$B$2:$B$1997,$A22),"")) -> 46022 | T22: =IF($A22="","",IFERROR(INDEX('4-VGP'!$A$2:$A$334,MATCH($A22,'4-VGP'!$N$2:$N$334,0)),"")) -> 45729 | W22: =IF($T22="","",EDATE($T22,'8-Param'!$Q$2)) -> 46094
R23: =IF($A23="","",IFERROR(_xlfn.MAXIFS('6-Historique'!$D$2:$D$1997,'6-Historique'!$B$2:$B$1997,$A23),"")) -> 45866 | T23: =IF($A23="","",IFERROR(INDEX('4-VGP'!$A$2:$A$334,MATCH($A23,'4-VGP'!$N$2:$N$334,0)),"")) -> 45729 | W23: =IF($T23="","",EDATE($T23,'8-Param'!$Q$2)) -> 46094
R24: =IF($A24="","",IFERROR(_xlfn.MAXIFS('6-Historique'!$D$2:$D$1997,'6-Historique'!$B$2:$B$1997,$A24),"")) -> 46195 | T24: =IF($A24="","",IFERROR(INDEX('4-VGP'!$A$2:$A$334,MATCH($A24,'4-VGP'!$N$2:$N$334,0)),"")) -> 45729 | W24: =IF($T24="","",EDATE($T24,'8-Param'!$Q$2)) -> 46094
R25: =IF($A25="","",IFERROR(_xlfn.MAXIFS('6-Historique'!$D$2:$D$1997,'6-Historique'!$B$2:$B$1997,$A25),"")) -> 0 | T25: =IF($A25="","",IFERROR(INDEX('4-VGP'!$A$2:$A$334,MATCH($A25,'4-VGP'!$N$2:$N$334,0)),"")) -> 45729 | W25: =IF($T25="","",EDATE($T25,'8-Param'!$Q$2)) -> 46094
R26: =IF($A26="","",IFERROR(_xlfn.MAXIFS('6-Historique'!$D$2:$D$1997,'6-Historique'!$B$2:$B$1997,$A26),"")) -> 0
R27: =IF($A27="","",IFERROR(_xlfn.MAXIFS('6-Historique'!$D$2:$D$1997,'6-Historique'!$B$2:$B$1997,$A27),"")) -> 0
R28: =IF($A28="","",IFERROR(_xlfn.MAXIFS('6-Historique'!$D$2:$D$1997,'6-Historique'!$B$2:$B$1997,$A28),"")) -> 0
R29: =IF($A29="","",IFERROR(_xlfn.MAXIFS('6-Historique'!$D$2:$D$1997,'6-Historique'!$B$2:$B$1997,$A29),"")) -> 0
R30: =IF($A30="","",IFERROR(_xlfn.MAXIFS('6-Historique'!$D$2:$D$1997,'6-Historique'!$B$2:$B$1997,$A30),"")) -> 0
R31: =IF($A31="","",IFERROR(_xlfn.MAXIFS('6-Historique'!$D$2:$D$1997,'6-Historique'!$B$2:$B$1997,$A31),"")) -> 0
R32: =IF($A32="","",IFERROR(_xlfn.MAXIFS('6-Historique'!$D$2:$D$1997,'6-Historique'!$B$2:$B$1997,$A32),"")) -> 0
R33: =IF($A33="","",IFERROR(_xlfn.MAXIFS('6-Historique'!$D$2:$D$1997,'6-Historique'!$B$2:$B$1997,$A33),"")) -> 0
R34: =IF($A34="","",IFERROR(_xlfn.MAXIFS('6-Historique'!$D$2:$D$1997,'6-Historique'!$B$2:$B$1997,$A34),"")) -> 0
R35: =IF($A35="","",IFERROR(_xlfn.MAXIFS('6-Historique'!$D$2:$D$1997,'6-Historique'!$B$2:$B$1997,$A35),"")) -> 0
R36: =IF($A36="","",IFERROR(_xlfn.MAXIFS('6-Historique'!$D$2:$D$1997,'6-Historique'!$B$2:$B$1997,$A36),"")) -> 0 | T36: =IF($A36="","",IFERROR(INDEX('4-VGP'!$A$2:$A$334,MATCH($A36,'4-VGP'!$N$2:$N$334,0)),"")) -> 45755 | W36: =IF($T36="","",EDATE($T36,'8-Param'!$Q$2)) -> 46120
R37: =IF($A37="","",IFERROR(_xlfn.MAXIFS('6-Historique'!$D$2:$D$1997,'6-Historique'!$B$2:$B$1997,$A37),"")) -> 0
R38: =IF($A38="","",IFERROR(_xlfn.MAXIFS('6-Historique'!$D$2:$D$1997,'6-Historique'!$B$2:$B$1997,$A38),"")) -> 0
R39: =IF($A39="","",IFERROR(_xlfn.MAXIFS('6-Historique'!$D$2:$D$1997,'6-Historique'!$B$2:$B$1997,$A39),"")) -> 0
R40: =IF($A40="","",IFERROR(_xlfn.MAXIFS('6-Historique'!$D$2:$D$1997,'6-Historique'!$B$2:$B$1997,$A40),"")) -> 0
R41: =IF($A41="","",IFERROR(_xlfn.MAXIFS('6-Historique'!$D$2:$D$1997,'6-Historique'!$B$2:$B$1997,$A41),"")) -> 0
...

Sheet 4-VGP
A2: 45748
A3: 45748
A4: 45748
A5: 46097
A6: 45729
A7: 45729
A8: 45729
A9: 45729
A10: 45729
A11: 45729
A12: 45729
A13: 45755
... A334: 46092

Sheet 5-Observations VGP
B2: 46097 | J2: 46097
B3: 46097 | J3: 46097
B4: 45748 | J4: 45748
B5: 45748 | J5: 45748
B6: 45748 | J6: 45748
B7: 45748 | J7: 45748
B8: 45748 | J8: 45748
B9: 45748 | J9: 45748
B10: 45748 | J10: 45748
B11: 45748 | J11: 45748
B12: 45748 | J12: 45748
B13: 45748 | J13: 45748
... B53: 43949 | J53: 45219
B54: 43949 | J54: 45748 | M54: 45076
B55: 44712 | J55: 45729
B56: 44207 | J56: 45729
B57: 45729 | J57: 45729
B58: 45729 | J58: 45729
B59: 45729 | J59: 45729
B60: 45729 | J60: 45729
B61: 45729 | J61: 45729
B62: 45729 | J62: 45729
B63: 45729 | J63: 45729
B64: 45729 | J64: 45729
B65: 45729 | J65: 45729
B66: 45729 | J66: 45729
... B100: 45307 | J100: 45289
B101: 44608 | J101: 45755 | M101: 45054
B102: 44770 | J102: 45755
B103: 44770 | J103: 45755
B104: 44770 | J104: 45755
B105: 44770 | J105: 45755
B106: 44770 | J106: 45755
B107: 44770 | J107: 45755
B108: 44770 | J108: 45755
B109: 44770 | J109: 46093
B110: 44770 | J110: 45755
B111: 44712 | J111: 45729
B112: 44207 | J112: 45729
B113: 44207 | J113: 45729
...

Sheet 6-Historique
D2: 46007
D3: 44043
D4: 45163
D5: 45114
D6: 45131
D7: 45166
D8: 45191
D9: 45225
D10: 45236
D11: 45359
D12: 45359
D13: 45681
... D1997: 45406

Sheet 7-Clients

Sheet 8-Param
